Workbook

Sheet Users
A1: Email | B1: Nama | C1: Role | D1: Unit
A2: umum@annahl-islamic.sch.id | B2: Super Admin | C2: Admin | D2: All
A3: ananda@annahl-islamic.sch.id | B3: Admin SD | C3: PIC | D3: SD
A4: ametriyadhi@annahl-islamic.sch.id | B4: Admin Litbang | C4: PIC | D4: Litbang dan SMM
A5: rahmad@annahl-islamic.sch.id | B5: Admin SMP | C5: PIC | D5: SMP
A6: sani@annahl-islamic.sch.id | B6: Admin PGTK | C6: PIC | D6: PGTK
A7: japar@annahl-islamic.sch.id | B7: Admin SMA | C7: PIC | D7: SMA
A8: ariefrn@annahl-islamic.sch.id | B8: User SDM | C8: PIC | D8: SDM
A9: ruri@annahl-islamic.sch.id | B9: User Litbang | C9: PIC | D9: Litbang dan SMM
A10: fadli@annahl-islamic.sch.id | B10: Admin Marketing | C10: PIC | D10: Marketing

Sheet Visi
A1: Menjadi bagian umum yang profesional dalam memberikan layanan prima untuk mendukung kegiatan belajar mengajar di An Nahl Islamic School

Sheet Misi
A1: Menyediakan dan memelihara sarana prasarana yang mendukung kegiatan belajar mengajar
A2: Memberikan pelayanan pengadaan barang dan jasa yang efektif dan efisien
A3: Menciptakan lingkungan sekolah yang aman, nyaman, bersih dan indah
A4: Memberikan layanan umum yang responsif dan profesional

Sheet Sasaran
A1: ID | B1: Sasaran Mutu | C1: Target | D1: Periode | E1: Metode
A2: S-001 | B2: Terlaksananya 90% Pengadaan dan Perbaikan Gedung dan Sarana Prasarana KBM | C2: 95 | D2: Tahunan dan Bulanan | E2: Melaksanakan permintaan pengadaan dan perbaikan sarpras dari tiap-tiap unit
A3: S-002 | B3: Terlaksananya 95% Permintaan Pengadaan Barang dan Jasa. | C3: 95 | D3: Tahunan dan Bulanan | E3: Ketersediaan sistem, Laporan Progres Berkala, Dokumentasi
A4: S-003 | B4: Tercapainya 95% Pemeliharaan dan Perbaikan Fasilitas KBM | C4: 95 | D4: Tahunan dan Bulanan | E4: Ketersediaan sistem, Laporan Progres Berkala, Dokumentasi
A5: S-004 | B5: Tercapainya minimal 90% ketersediaan dan kelancaran Layanan Umum | C5: 90 | D5: Tahunan dan Bulanan | E5: Ketersediaan sistem, Laporan Progres Berkala, Dokumentasi
A6: S-005 | B6: Terciptanya 90% keamanan, kenyamanan, dan kondusifitas KBM | C6: 90 | D6: Tahunan dan Bulanan | E6: Laporan Buku Piket Security, Laporan Check Point
A7: S-006 | B7: Terwujudnya 90% kebersihan dan keindahan Sekolah | C7: 90 | D7: Tahunan dan Bulanan | E7: Ceklist Monitoring dan Pemeliharaan, Laporan ceklist kebersihan, Laporan Check Point

Sheet StrukturOrganisasi
A1: ID | B1: Jabatan | C1: Nama
A2: 1 | B2: Kepala Bagian Umum | C2: Slamet Haryadi
A3: 2 | B3: Koordinator Security | C3: Jaka
A4: 3 | B4: Koordinator OB | C4: Masdik
A5: 4 | B5: Penanggung Jawab Sarpras | C5: Anen
A6: 5 | B6: Anggota Security | C6: Tim Security
A7: 6 | B7: Anggota OB | C7: Tim OB

Sheet ProgramKerja
A1: ID | B1: Nama Induk | C1: Nama Sub-Prom | D1: Tipe | E1: IndukID | F1: PJ | G1: Unit | H1: Timeline | I1: Prioritas | J1: Anggaran | K1: Catatan | L1: Status | M1: Jumlah
A2: P-001 | B2: Pengadaan dan Perbaikan Sarana dan Prasarana | C2: Pengadaan dan Perbaikan sarana prasarana pennunjang KBM sesuai dengan kebutuhan | D2: Induk | F2: PIC Sarpras Umum | H2: 20 Juni - 10 Juli 2025 | L2: Belum Dimulai
A3: P-002 | B3: Pengadaan Barang dan Jasa | C3: Pengadaan semua kebutuhan yang dapat mensupport KBM sesuai dengan permintaan unit | D3: Induk | F3: Slamet Haryadi | H3: 1 Juli 2025 | L3: Belum Dimulai
A4: P-003 | B4: Pemeliharaan dan Perbaikan | C4: Pemeliharaan baik yang bersifat rutin atau berkala dan perbaikan fasilitas pendukung kbm | D4: Induk | F4: PIC Sarpras Umum | H4: Tiap Bulan | L4: Belum Dimulai
A5: P-004 | B5: Layanan Penggunaan Fasilitas | C5: Pelayanan Penggunaan Fasilitas Umum Bersama dan Fasilitas Penunjang KBM | D5: Induk | L5: Belum Dimulai
A6: P-005 | B6: Peminjaman dan Pengmbalian Barang | C6: Pelayanan Peminjaman Barang untuk Support Kegiatan Unit | D6: Induk | L6: Belum Dimulai
A7: P-006 | B7: Penggunaan Barang Habi Pakai | C7: Pelayanan Penyediaan Barang Habis Pakai untuk kelancaran Kegiatan Pembelajaran | D7: Induk | L7: Belum Dimulai
A8: P-007 | B8: Keamanan, Kenyamanan dan Kondusifitas Lingkungan Sekolah | C8: Pelayanan Penyediaan Barang Habis Pakai untuk kelancaran Kegiatan Pembelajaran | D8: Induk | L8: Belum Dimulai
A9: P-008 | B9: Kebersihan dan Keindahan Sekolah | C9: Pelayanan Penyediaan Barang Habis Pakai untuk kelancaran Kegiatan Pembelajaran | D9: Induk | L9: Belum Dimulai
A10: P-009 | B10: Pembinaan Anggota Security dan Tim OB | C10: Pelatihan dan Pembinaan Anggota Security dan Tim OB untuk peningkatan kinerja dan ibadah | D10: Induk | L10: Belum Dimulai
A11: SUB-001 | B11: Pengadaan dan Perbaikan Sarana dan Prasarana | C11: Pembuatan Rangka Spanduk (Samping Koperasi & Perpustakaan) | D11: Sub | E11: P-001 | F11: PIC Sarpras Umum | G11: SD | H11: 20 Juni - 10 Juli 2025 | I11: Sedang | J11: =3920000+1710000 -> 5630000 | L11: Belum Dimulai
A12: SUB-002 | B12: Pengadaan dan Perbaikan Sarana dan Prasarana | C12: Perbaikan Umbul2 | D12: Sub | E12: P-001 | F12: PIC Sarpras Umum | G12: Marketing | H12: 20 Juni - 10 Juli 2025 | I12: Sedang | J12: =258000+150000 -> 408000 | L12: Belum Dimulai
A13: SUB-003 | B13: Pengadaan dan Perbaikan Sarana dan Prasarana | C13: Pembuatan Catur Jalan Pedestrian | D13: Sub | E13: P-001 | F13: PIC Sarpras Umum | G13: Umum | H13: 20 Juni - 10 Juli 2025 | I13: Sedang | J13: =9990000+1425000+3500000 -> 14915000 | L13: Belum Dimulai
A14: SUB-004 | B14: Pengadaan dan Perbaikan Sarana dan Prasarana | C14: Perbaikan Jalan Utama Berlubang | D14: Sub | E14: P-001 | F14: PIC Sarpras Umum | G14: Umum | H14: 20 Juni - 10 Juli 2025 | J14: 3165000 | L14: Belum Dimulai
A15: SUB-005 | B15: Pengadaan dan Perbaikan Sarana dan Prasarana | C15: Pemasangan Paping Block Playground SD (Kapal) | D15: Sub | E15: P-001 | F15: PIC Sarpras Umum | G15: Ecopark | H15: 20 Juni - 10 Juli 2025 | I15: Tinggi | J15: =3300000+1425000 -> 4725000 | L15: Belum Dimulai
A16: SUB-006 | B16: Pengadaan dan Perbaikan Sarana dan Prasarana | C16: Perbaikan Talang di Saung An Nur | D16: Sub | E16: P-001 | F16: PIC Sarpras Umum | G16: Ecopark | H16: 20 Juni - 10 Juli 2025 | J16: =330000+855000 -> 1185000 | L16: Belum Dimulai
A17: SUB-007 | B17: Pengadaan dan Perbaikan Sarana dan Prasarana | C17: Pengecetan Ruang Kelas Gedung C Lantai 1 | D17: Sub | E17: P-001 | F17: PIC Sarpras Umum | G17: SMP | H17: 20 Juni - 10 Juli 2025 | J17: =7430000+1710000 -> 9140000 | L17: Belum Dimulai
A18: SUB-009 | B18: Pengadaan dan Perbaikan Sarana dan Prasarana | C18: Pengecetan Gedung B Luar | D18: Sub | E18: P-001 | F18: PIC Sarpras Umum | G18: SD | H18: 20 Juni - 10 Juli 2025 | J18: =22680000+17100000 -> 39780000 | L18: Belum Dimulai
A19: SUB-010 | B19: Pengadaan dan Perbaikan Sarana dan Prasarana | C19: Pengecatan Lorong SD Warna Ceria | D19: Sub | E19: P-001 | F19: PIC Sarpras Umum | G19: SD | H19: 20 Juni - 10 Juli 2025 | J19: =2070000+1710000 -> 3780000 | L19: Belum Dimulai
A20: SUB-011 | B20: Pengadaan dan Perbaikan Sarana dan Prasarana | C20: Perbaikan Tempat Wudhu SD Lantai 1 | D20: Sub | E20: P-001 | F20: PIC Sarpras Umum | G20: SD | H20: 20 Juni - 10 Juli 2025 | J20: =2460000+1425000 -> 3885000 | L20: Belum Dimulai
A21: SUB-012 | B21: Pengadaan dan Perbaikan Sarana dan Prasarana | C21: Pengecetan Lorong Lantai 3 Gedung B | D21: Sub | E21: P-001 | F21: PIC Sarpras Umum | G21: SD | H21: 20 Juni - 10 Juli 2025 | J21: =764000+855000 -> 1619000 | L21: Belum Dimulai
A22: SUB-013 | B22: Pengadaan dan Perbaikan Sarana dan Prasarana | C22: Ganti list kemarik Tangga Gedung B | D22: Sub | E22: P-001 | F22: PIC Sarpras Umum | G22: SD | H22: 20 Juni - 10 Juli 2025 | J22: =240000+570000 -> 810000 | L22: Belum Dimulai
A23: SUB-014 | B23: Pengadaan dan Perbaikan Sarana dan Prasarana | C23: Perbaikan Perpustakaan SD | D23: Sub | E23: P-001 | F23: PIC Sarpras Umum | G23: SD | H23: 20 Juni - 10 Juli 2025 | J23: =240000+630000+2010000 -> 2880000 | L23: Belum Dimulai
A24: SUB-015 | B24: Pengadaan dan Perbaikan Sarana dan Prasarana | C24: Perbaikan Ruang FO | D24: Sub | E24: P-001 | F24: PIC Sarpras Umum | G24: Umum | H24: 20 Juni - 10 Juli 2025 | J24: 0 | L24: Belum Dimulai
A25: SUB-016 | B25: Pengadaan dan Perbaikan Sarana dan Prasarana | C25: Kanopi Keliling area sekolah | D25: Sub | E25: P-001 | F25: PIC Sarpras Umum | G25: Ecopark | H25: 20 Juni - 10 Juli 2025 | J25: 0 | L25: Belum Dimulai
A26: SUB-017 | B26: Pengadaan dan Perbaikan Sarana dan Prasarana | C26: Koperasi Sekolah | D26: Sub | E26: P-001 | F26: PIC Sarpras Umum | G26: Umum | H26: 20 Juni - 10 Juli 2025 | J26: 0 | L26: Belum Dimulai
A27: SUB-018 | B27: Pengadaan dan Perbaikan Sarana dan Prasarana | C27: Pos Security | D27: Sub | E27: P-001 | F27: PIC Sarpras Umum | G27: Umum | H27: 20 Juni - 10 Juli 2025 | J27: 0 | L27: Belum Dimulai
A28: SUB-019 | B28: Pengadaan dan Perbaikan Sarana dan Prasarana | C28: Kantin Sekolah | D28: Sub | E28: P-001 | F28: PIC Sarpras Umum | G28: Umum | H28: 20 Juni - 10 Juli 2025 | J28: 0 | L28: Belum Dimulai
A29: SUB-020 | B29: Pengadaan dan Perbaikan Sarana dan Prasarana | C29: Perbaikan Ruang FO | D29: Sub | E29: P-001 | F29: PIC Sarpras Umum | G29: Umum | H29: 20 Juni - 10 Juli 2025 | J29: 0 | L29: Belum Dimulai
A30: SUB-021 | B30: Pengadaan dan Perbaikan Sarana dan Prasarana | C30: Perpus dan Lab gedung C | D30: Sub | E30: P-001 | F30: PIC Sarpras Umum | G30: SMP & SMA | H30: 20 Juni - 10 Juli 2025 | J30: 0 | L30: Belum Dimulai
A31: SUB-022 | B31: Pengadaan dan Perbaikan Sarana dan Prasarana | C31: Central Blower PGTK (Aula TK) | D31: Sub | E31: P-001 | F31: PIC Sarpras Umum | G31: PGTK | H31: 20 Juni - 10 Juli 2025 | J31: 0 | L31: Belum Dimulai
A32: SUB-023 | B32: Pengadaan dan Perbaikan Sarana dan Prasarana | C32: CCTV Area Ecopark | D32: Sub | E32: P-001 | F32: PIC Sarpras Umum | G32: Ecopark | H32: 20 Juni - 10 Juli 2025 | J32: 12000000 | L32: Belum Dimulai
A33: SUB-024 | B33: Pengadaan dan Perbaikan Sarana dan Prasarana | C33: Perbaikan Pedestrian | D33: Sub | E33: P-001 | F33: PIC Sarpras Umum | G33: Ecopark | H33: 20 Juni - 10 Juli 2025 | I33: Rendah | J33: 5000000 | L33: Belum Dimulai
A34: SUB-025 | B34: Pengadaan dan Perbaikan Sarana dan Prasarana | C34: CCTV SMP 2 titik | D34: Sub | E34: P-001 | F34: PIC Sarpras Umum | G34: SMP | H34: 20 Juni - 10 Juli 2025 | J34: 4000000 | L34: Belum Dimulai
A35: SUB-026 | B35: Pengadaan dan Perbaikan Sarana dan Prasarana | C35: Revarasi Sofa Hexagon SD | D35: Sub | E35: P-001 | F35: PIC Sarpras Umum | G35: SD | H35: 20 Juni - 10 Juli 2025 | I35: Tinggi | J35: 0 | L35: Belum Dimulai
A36: SUB-027 | B36: Pengadaan dan Perbaikan Sarana dan Prasarana | C36: Revarasi Sofa Lobi SMP | D36: Sub | E36: P-001 | F36: PIC Sarpras Umum | G36: SMP | H36: 20 Juni - 10 Juli 2025 | L36: Belum Dimulai
A37: SUB-028 | B37: Pengadaan dan Perbaikan Sarana dan Prasarana | C37: Pembuatan tempat wudhu lantai 2 ISBI | D37: Sub | E37: P-001 | F37: PIC Sarpras Umum | G37: Umum | H37: 20 Juni - 10 Juli 2025 | J37: =468000+855000 -> 1323000 | L37: Belum Dimulai
A38: SUB-029 | B38: Pengadaan Barang dan Jasa | C38: Pengadaan Laptop untuk Admin IT (Laptop yang ada sudah sering hang karena laptop limpahan dari tim kreatif sudah sering ngehang) | D38: Sub | E38: P-002 | F38: Slamet Haryadi | G38: Litbang dan SMM | H38: 2 Juli 2025 | J38: 10000000 | L38: Belum Dimulai
A39: SUB-030 | B39: Pengadaan Barang dan Jasa | C39: Pengadaan Plaud AI Note untuk notulensi rapat | D39: Sub | E39: P-002 | F39: Slamet Haryadi | G39: Litbang dan SMM | H39: 3 Juli 2025 | J39: 2000000 | L39: Belum Dimulai
A40: SUB-031 | B40: Pengadaan Barang dan Jasa | C40: Kipas plafon | D40: Sub | E40: P-002 | F40: PIC Unit PGTK | G40: PGTK | H40: Juli 2025 | I40: Low | J40: 2500000 | L40: Belum Dimulai | M40: 5
...

Sheet APBS
A1: ID | B1: Kode | C1: Uraian | D1: anggaran | E1: Keterangan
A2: A-001 | B2: 51411-001 | C2: Pemeliharaan Gedung | D2: 72234300 | E2: 12 Bulan. | F2: =D2/12 -> 6019525
A3: A-002 | B3: 51411-002 | C3: Pemeliharaan Kolam Renang - Obat Kolam Renang | D3: 15000000 | E3: 6 Bulan | F3: =D3/6 -> 2500000
A4: A-003 | B4: 51411-003 | C4: Pemeliharaan Kolam Renang - Treatment Vacum | D4: 3687500 | E4: 12 Bulan | F4: =D4/12 -> 307291.67
A5: A-004 | B5: 51411-004 | C5: Pemeliharaan Sarpras | D5: 27000000 | E5: 12 Bulan | F5: =D5/12 -> 2250000
A6: A-005 | B6: 51411-005 | C6: Pemeliharaan Kendaraan Operasional - Service Motor | D6: 1000000 | E6: 12 Bulan | F6: =D6/12 -> 83333.333
A7: A-006 | B7: 51411-006 | C7: Pemeliharaan Kendaraan Operasional - Service Mobil | D7: 11477648 | E7: 12 Bulan | F7: =D7/12 -> 956470.67
A8: A-007 | B8: 51411-007 | C8: Pemeliharaan Kendaraan Operasional - Pajak Motor | D8: 200000 | E8: 12 Bulan | F8: =D8/12 -> 16666.667
A9: A-008 | B9: 51411-008 | C9: Pemeliharaan Kendaraan Operasional - Pajak Mobil (4 kendaraan) | D9: 14124000 | E9: 12 Bulan | F9: =D9/12 -> 1177000
A10: A-009 | B10: 51411-009 | C10: Pemeliharaan Barang Inventaris | D10: 27436785 | E10: 12 Bulan | F10: =D10/12 -> 2286398.8
A11: A-010 | B11: 51411-010 | C11: Pemeliharaan lainnya - Fogging | D11: 1500000 | E11: 12 Bulan | F11: =D11/12 -> 125000
A12: A-011 | B12: 51411-011 | C12: Pemeliharaan AC- Cuci | D12: 25000000 | E12: 12 Bulan | F12: =D12/12 -> 2083333.3
A13: A-012 | B13: 51411-012 | C13: Pemeliharaan AC- Service | D13: 7500000 | E13: 12 Bulan | F13: =D13/12 -> 625000
A14: A-013 | B14: 51412-001 | C14: Biaya Perizinan | D14: 1000000 | E14: 12 Bulan | F14: =D14/12 -> 83333.333
A15: A-014 | B15: 51412-002 | C15: Keamanan & Kebersihan Lingkungan - CSR Lingkungan | D15: 42900000 | E15: 12 Bulan | F15: =D15/12 -> 3575000
... A18: A-017 | B18: 51412-005 | C18: Sewa Ecopark & Ruang ISBI | D18: 0 | E18: 12 Bulan | F18: =D18/12 -> 0
A19: A-018 | B19: 51412-006 | C19: Administrasi Operasional lainnya - Petty Cash | D19: =2200000*12 -> 26400000 | E19: 12 Bulan | F19: =D19/12 -> 2200000
A20: A-019 | B20: 51412-007 | C20: Konsumsi Olahraga Security | D20: 3000000 | E20: 12 Bulan | F20: =D20/12 -> 250000
A21: A-020 | B21: 51412-008 | C21: Pelatihan SDM Umum; Gawat Darurat & P3K | D21: 4000000 | E21: 12 Bulan | F21: =D21/12 -> 333333.33
A22: A-021 | B22: 51413-001 | C22: Listrik | D22: 2.8101477e+08 | E22: 12 Bulan | F22: =D22/12 -> 23417897
A23: A-022 | B23: 51413-002 | C23: Telephon dan Internet | D23: 181923885 | E23: 12 Bulan | F23: =D23/12 -> 15160324
A24: A-023 | B24: 51413-003 | C24: Air Mineral | D24: =4000000*12 -> 48000000 | E24: 12 Bulan | F24: =D24/12 -> 4000000
A25: A-024 | B25: 51414-001 | C25: ATK - Kertas A4 & F4 | D25: 2000000 | E25: 12 Bulan | F25: =D25/12 -> 166666.67
A26: A-025 | B26: 51414-002 | C26: ATK - ATK Lainnya | D26: 4500000 | E26: 12 Bulan | F26: =D26/12 -> 375000
A27: A-026 | B27: 51414-003 | C27: Barang habis pakai - Tinta Printer | D27: 9527796 | E27: 12 Bulan | F27: =D27/12 -> 793983
A28: A-027 | B28: 51414-004 | C28: Barang habis pakai - Barang Lainnya | D28: 46948400 | E28: 12 Bulan | F28: =D28/12 -> 3912366.7
A29: A-028 | B29: 51414-005 | C29: Perlengkapan Umum / Sekolah | D29: 33965170 | E29: 12 Bulan | F29: =D29/12 -> 2830430.8
A30: A-029 | B30: 51415-001 | C30: Investasi PGTK | D30: ='Investasi Unit'!B6 -> 49990000 | E30: 1 Kali/ Tahun | F30: =D30/12 -> 4165833.3
A31: A-030 | B31: 51415-002 | C31: Investasi SD | D31: ='Investasi Unit'!B7 -> 168039000 | E31: 1 Kali/ Tahun | F31: =D31/12 -> 14003250
A32: A-031 | B32: 51415-003 | C32: Investasi SMP | D32: ='Investasi Unit'!B9+'Investasi Unit'!B10 -> 167385900 | E32: 1 Kali/ Tahun | F32: =D32/12 -> 13948825
A33: A-032 | B33: 51415-004 | C33: Investasi SMA | D33: ='Investasi Unit'!B8 -> 121240000 | E33: 1 Kali/ Tahun | F33: =D33/12 -> 10103333
A34: A-033 | B34: 51415-005 | C34: Investasi Umum | D34: ='Investasi Unit'!B3+'Investasi Unit'!B4+'Investasi Unit'!B5+'Investasi Unit'!B11 -> 72071000 | E34: 1 Kali/ Tahun | F34: =D34/12 -> 6005916.7
A35: A-034 | B35: 51415-006 | C35: Investasi Yayasan | D35: ='Rincian Anggaran'!Q4 -> 122910000 | E35: 1 Kali/ Tahun | F35: =D35/12 -> 10242500

Sheet Investasi Unit
A1: =IFERROR(__xludf.DUMMYFUNCTION("QUERY(ProgramKerja!A:M, ""SELECT G, SUM(J) GROUP BY G LABEL SUM(J) 'Total Pengeluaran'"", 1)"),"Unit") -> Unit | B1: =IFERROR(__xludf.DUMMYFUNCTION("""COMPUTED_VALUE"""),"Total Pengeluaran") -> Total Pengeluaran
A3: =IFERROR(__xludf.DUMMYFUNCTION("""COMPUTED_VALUE"""),"Ecopark") -> Ecopark | B3: =IFERROR(__xludf.DUMMYFUNCTION("""COMPUTED_VALUE"""),2.291E7) -> 22910000
A4: =IFERROR(__xludf.DUMMYFUNCTION("""COMPUTED_VALUE"""),"Litbang dan SMM") -> Litbang dan SMM | B4: =IFERROR(__xludf.DUMMYFUNCTION("""COMPUTED_VALUE"""),1.435E7) -> 14350000
A5: =IFERROR(__xludf.DUMMYFUNCTION("""COMPUTED_VALUE"""),"Marketing") -> Marketing | B5: =IFERROR(__xludf.DUMMYFUNCTION("""COMPUTED_VALUE"""),408000.0) -> 408000
A6: =IFERROR(__xludf.DUMMYFUNCTION("""COMPUTED_VALUE"""),"PGTK") -> PGTK | B6: =IFERROR(__xludf.DUMMYFUNCTION("""COMPUTED_VALUE"""),4.999E7) -> 49990000
A7: =IFERROR(__xludf.DUMMYFUNCTION("""COMPUTED_VALUE"""),"SD") -> SD | B7: =IFERROR(__xludf.DUMMYFUNCTION("""COMPUTED_VALUE"""),1.68039E8) -> 168039000
A8: =IFERROR(__xludf.DUMMYFUNCTION("""COMPUTED_VALUE"""),"SMA") -> SMA | B8: =IFERROR(__xludf.DUMMYFUNCTION("""COMPUTED_VALUE"""),1.2124E8) -> 121240000
A9: =IFERROR(__xludf.DUMMYFUNCTION("""COMPUTED_VALUE"""),"SMP") -> SMP | B9: =IFERROR(__xludf.DUMMYFUNCTION("""COMPUTED_VALUE"""),1.673859E8) -> 167385900
A10: =IFERROR(__xludf.DUMMYFUNCTION("""COMPUTED_VALUE"""),"SMP & SMA") -> SMP & SMA | B10: =IFERROR(__xludf.DUMMYFUNCTION("""COMPUTED_VALUE"""),0.0) -> 0
A11: =IFERROR(__xludf.DUMMYFUNCTION("""COMPUTED_VALUE"""),"Umum") -> Umum | B11: =IFERROR(__xludf.DUMMYFUNCTION("""COMPUTED_VALUE"""),3.4403E7) -> 34403000
A13: Total | B13: =SUM(B3:B11) -> 578725900
B14: ='Rincian Anggaran'!Q4 -> 122910000
B15: =B13+B14 -> 701635900

Sheet Rincian Anggaran
B1: 45863 | C1: 45894 | D1: 45925 | E1: 45955 | F1: 45986 | G1: 46016 | H1: 46047 | I1: 46078 | J1: 46106 | K1: 46137 | L1: 46167 | M1: 46198 | N1: Rata-rata | O1: =10% -> 0.1 | P1: Anggaran | Q1: Jumlah
A2: Anggsuran Mobil Operasional | B2: 4380000 | C2: 4380000 | D2: 4380000 | E2: 4380000 | F2: 4380000 | G2: 4380000 | H2: 4380000 | I2: 4380000 | J2: 4380000 | K2: 4380000 | L2: 4380000 | M2: 4380000 | N2: =AVERAGE(B2:M2) -> 4380000 | P2: =N2+O2 -> 4380000 | Q2: =P2*12 -> 52560000
A3: Anggsuran Mobil Direksi | B3: 14070000 | C3: 14070000 | D3: 14070000 | E3: 14070000 | F3: 14070000 | N3: =AVERAGE(B3:M3) -> 14070000 | P3: =N3+O3 -> 14070000 | Q3: =P3*5 -> 70350000
Q4: =SUM(Q2:Q3) -> 122910000
A6: Listrik An Nahl | B6: 7317760 | C6: 7635769 | D6: 11584789 | E6: 11287222 | F6: 14344049 | G6: 12517488 | H6: 7381538 | I6: 9948957 | J6: 10705359 | K6: 7317760 | L6: 9632479 | M6: 10654831 | N6: =AVERAGE(B6:M6) -> 10027333 | O6: =N6*10% -> 1002733.3 | P6: =N6+O6 -> 11030067 | Q6: =P6*12 -> 1.323608e+08
A7: Listrik YPPI | B7: 13927125 | C7: 12411675 | D7: 13363114 | E7: 12527643 | F7: 14301690 | G7: 11664468 | H7: 8528056 | I7: 10139368 | J7: 10288429 | K7: 7070256 | L7: 9833736 | M7: 11084411 | N7: =AVERAGE(B7:M7) -> 11261664 | O7: =N7*10% -> 1126166.4 | P7: =N7+O7 -> 12387831 | Q7: =P7*12 -> 1.4865397e+08 | R7: =Q6+Q7 -> 2.8101477e+08
A8: Internet & Telepon An Nahl & Speddy | B8: 1012550 | C8: 1012550 | D8: 1012550 | E8: 1012550 | F8: 1012550 | G8: 1012550 | H8: 1012550 | I8: 1018100 | J8: 1018100 | K8: 1018100 | L8: 1018100 | M8: 1015100 | N8: =AVERAGE(B8:M8) -> 1014612.5 | O8: =N8*10% -> 101461.25 | P8: =N8+O8 -> 1116073.8 | Q8: =P8*12 -> 13392885
A9: Internet Maxindo | B9: 12767500 | C9: 12767500 | D9: 12767500 | E9: 12767500 | F9: 12767500 | G9: 12767500 | H9: 12767500 | I9: 12767500 | J9: 12767500 | K9: 12767500 | L9: 12767500 | M9: 12767500 | N9: =AVERAGE(B9:M9) -> 12767500 | O9: =N9*10% -> 1276750 | P9: =N9+O9 -> 14044250 | Q9: =P9*12 -> 168531000 | R9: =Q8+Q9 -> 181923885
A10: Air Galon TDS | B10: 1805000 | C10: 3167100 | D10: 4819500 | E10: 3916800 | F10: 4834800 | G10: 4528800 | H10: 1897200 | I10: 3335400 | J10: 3320100 | K10: 1.050.000 | L10: 3503700 | N10: =AVERAGE(B10:M10) -> 3512840 | O10: =N10*10% -> 351284 | P10: =N10+O10 -> 3864124 | Q10: =P10*12 -> 46369488
A11: Uang Lingkungan | B11: 3322500 | C11: 3322500 | D11: 3322500 | E11: 3322500 | F11: 3322500 | G11: 3322500 | H11: 3322500 | I11: 3322500 | J11: 3322500 | K11: 3322500 | L11: 3322500 | M11: 3322500 | N11: =AVERAGE(B11:M11) -> 3322500 | O11: =N11*10% -> 332250 | P11: =N11+O11 -> 3654750 | Q11: =P11*12 -> 43857000
A12: Konsusmsi OR Security | B12: 247500 | C12: 247500 | D12: 247500 | E12: 247500 | F12: 247500 | G12: 247500 | H12: 247500 | I12: 247500 | J12: 247500 | K12: 247500 | L12: 247500 | M12: 247500 | N12: =AVERAGE(B12:M12) -> 247500 | O12: =N12*30% -> 74250 | P12: =N12+O12 -> 321750 | Q12: =P12*12 -> 3861000
A13: Chemical Kolam Renang | B13: 633500 | C13: 560000 | D13: 427500 | F13: 1160000 | H13: 552500 | I13: 1075000 | J13: 802500 | K13: 1050000 | N13: =AVERAGE(B13:M13) -> 782625 | O13: =N13*10% -> 78262.5 | P13: =N13+O13 -> 860887.5 | Q13: =P13*12 -> 10330650
A14: Belanja Bulanan | B14: 3753800 | C14: 4334100 | D14: 3652200 | E14: 3651500 | F14: 3470900 | G14: 4120700 | H14: 4297900 | I14: 3643160 | J14: 4573900 | K14: 3595100 | L14: 4073600 | N14: =AVERAGE(B14:M14) -> 3924260 | O14: =N14*10% -> 392426 | P14: =N14+O14 -> 4316686 | Q14: =P14*12 -> 51800232
A15: Perkap GA | B15: 2007880 | C15: 2251600 | D15: 1969640 | E15: 1848500 | F15: 2630930 | G15: 750700 | H15: 631700 | I15: 1969400 | J15: 1149000 | K15: 1163000 | L15: 1147750 | N15: =AVERAGE(B15:M15) -> 1592736.4 | O15: =N15*10% -> 159273.64 | P15: =N15+O15 -> 1752010 | Q15: =P15*12 -> 21024120
A16: Patty Cash Umum | B16: 2000000 | C16: 2000000 | D16: 2000000 | E16: 2000000 | F16: 2000000 | G16: 2000000 | H16: 2000000 | I16: 2000000 | J16: 2000000 | K16: 2000000 | L16: 2000000 | M16: 2000000 | N16: =AVERAGE(B16:M16) -> 2000000 | O16: =N16*10% -> 200000 | P16: =N16+O16 -> 2200000 | Q16: =P16*12 -> 26400000

Sheet Anggaran Fix
A1: Anggaran Yang Disepakati untuk unit GA | E1: Marketing
A2: Aspek | B2: Anggaran | E2: Laptop | F2: 7500000
A3: Unit GA | B3: 875000000 | E3: SignSystem | F3: 25000000
A4: Unit Investasi | B4: 650000000
B5: =SUM(B3:B4) -> 1525000000
B6: =SUM(APBS!D2:D35) -> 1619198653
B7: =B6-B5 -> 94198653
E8: PGTK | F8: 65000000
E9: SD | F9: 140000000
E10: SMP | F10: 110000000
E11: SMA | F11: 90000000
E12: Yayasan | F12: 122910000
F13: =SUM(F8:F12) -> 527910000
E14: Umum | F14: =B4-F13 -> 122090000
D18: 1553581796
D19: =B5-D18 -> -28581796
